Workbook
Name _3t21pjvpxv31: Task2!$A$6
Name Days: [1]DataValidation!$V$2:$V$20
Name Dy: OFFSET([1]Offset!$A$1,0,0,COUNTA([1]Offset!$A:$A),COUNTA([1]Offset!$1:$1))
Name DynamicRange: OFFSET([1]Offset!$A$1,0,0,COUNTA([1]Offset!$A:$A),COUNTA([1]Offset!$1:$1))
Name DynamicTable: OFFSET([2]PivotTable1.2!$A$1,0,0,COUNTA([2]PivotTable1.2!$A:$A),COUNTA([2]PivotTable1.2!$1:$1))
Name HR_Header: #REF!
Name MonthlyIncome: [3]NamedRange!$O$3:$O$1472
Name MonthlyRate: [3]NamedRange!$P$3:$P$1472
Name NativeTimeline_Order_Date: #N/A
Name OrdId: [4]VLookUp!$A$1:$A$4577
Name Quantity: [4]MathsFunctions!$D$3:$D$22
Name Slicer_Delivery_Status: #N/A
Name Slicer_Payment_Method: #N/A
Name Slicer_Region: #N/A

Sheet AmazonSales
A1: Order ID | B1: Order Date | C1: Delivery Date | D1: Cancel Date | E1: Customer ID | F1: Product ID | G1: Region | H1: Sale Price/Unit | I1: Quantity | J1: Total Amount | K1: Payment Method | L1: Delivery Status | M1: Fulfillment Partner
A2: ORD0001 | B2: 12/31/2023 | D2: 1/2/2024 | E2: CUST021 | F2: PROD012 | G2: North | H2: 44 | I2: 1 | J2: 44 | K2: Apple Pay | L2: Cancelled | M2: DHL
A3: ORD0002 | B3: 2/22/2023 | C3: 2/24/2023 | E3: CUST029 | F3: PROD018 | G3: East | H3: 96 | I3: 4 | J3: 384 | K3: Credit Card | L3: Delivered | M3: DHL
A4: ORD0003 | B4: 10/11/2023 | E4: CUST021 | F4: PROD013 | G4: South | H4: 194 | I4: 4 | J4: 776 | K4: Credit Card | L4: In Transit | M4: USPS
A5: ORD0004 | B5: 5/5/2023 | D5: 5/11/2023 | E5: CUST044 | F5: PROD013 | G5: North | H5: 196 | I5: 3 | J5: 588 | K5: PayPal | L5: Cancelled | M5: UPS
A6: ORD0005 | B6: 2/2/2023 | C6: 2/5/2023 | E6: CUST027 | F6: PROD010 | G6: North | H6: 59 | I6: 1 | J6: 59 | K6: PayPal | L6: Delivered | M6: Amazon Logistics
A7: ORD0006 | B7: 11/1/2023 | D7: 11/2/2023 | E7: CUST009 | F7: PROD010 | G7: North | H7: 58 | I7: 4 | J7: 232 | K7: Amazon Pay | L7: Cancelled | M7: DHL
A8: ORD0007 | B8: 8/14/2023 | D8: 8/18/2023 | E8: CUST042 | F8: PROD020 | G8: Central | H8: 105 | I8: 3 | J8: 315 | K8: Debit Card | L8: Cancelled | M8: DHL
A9: ORD0008 | B9: 4/1/2023 | D9: 4/6/2023 | E9: CUST019 | F9: PROD021 | G9: West | H9: 37 | I9: 5 | J9: 185 | K9: PayPal | L9: Cancelled | M9: DHL
A10: ORD0009 | B10: 7/21/2023 | E10: CUST013 | F10: PROD019 | G10: Central | H10: 44 | I10: 2 | J10: 88 | K10: Credit Card | L10: In Transit | M10: Amazon Logistics
A11: ORD0010 | B11: 12/29/2023 | E11: CUST019 | F11: PROD003 | G11: South | H11: 141 | I11: 4 | J11: 564 | K11: Debit Card | L11: In Transit | M11: DHL
A12: ORD0011 | B12: 5/4/2023 | D12: 5/8/2023 | E12: CUST046 | F12: PROD014 | G12: South | H12: 249 | I12: 1 | J12: 249 | K12: Amazon Pay | L12: Cancelled | M12: USPS
A13: ORD0012 | B13: 7/25/2023 | E13: CUST045 | F13: PROD014 | G13: Central | H13: 247 | I13: 3 | J13: 741 | K13: Amazon Pay | L13: In Transit | M13: FedEx
A14: ORD0013 | B14: 2/25/2023 | D14: 2/28/2023 | E14: CUST023 | F14: PROD006 | G14: Central | H14: 96 | I14: 1 | J14: 96 | K14: Apple Pay | L14: Cancelled | M14: Amazon Logistics
A15: ORD0014 | B15: 2/24/2023 | D15: 2/25/2023 | E15: CUST033 | F15: PROD017 | G15: West | H15: 74 | I15: 5 | J15: 370 | K15: Apple Pay | L15: Cancelled | M15: Amazon Logistics
A16: ORD0015 | B16: 8/26/2023 | D16: 9/2/2023 | E16: CUST033 | F16: PROD005 | G16: South | H16: 27 | I16: 1 | J16: 27 | K16: Credit Card | L16: Cancelled | M16: Amazon Logistics
A17: ORD0016 | B17: 2/13/2023 | E17: CUST047 | F17: PROD005 | G17: South | H17: 27 | I17: 3 | J17: 81 | K17: Debit Card | L17: In Transit | M17: Amazon Logistics
A18: ORD0017 | B18: 6/28/2023 | C18: 7/1/2023 | E18: CUST045 | F18: PROD015 | G18: East | H18: 21 | I18: 3 | J18: 63 | K18: Credit Card | L18: Delivered | M18: DHL
A19: ORD0018 | B19: 11/28/2023 | E19: CUST011 | F19: PROD008 | G19: West | H19: 70 | I19: 5 | J19: 350 | K19: PayPal | L19: In Transit | M19: Amazon Logistics
A20: ORD0019 | B20: 8/25/2023 | E20: CUST041 | F20: PROD006 | G20: South | H20: 94 | I20: 4 | J20: 376 | K20: Credit Card | L20: In Transit | M20: USPS
A21: ORD0020 | B21: 4/12/2023 | E21: CUST025 | F21: PROD001 | G21: North | H21: 813 | I21: 2 | J21: 1626 | K21: Credit Card | L21: In Transit | M21: FedEx
A22: ORD0021 | B22: 10/2/2023 | E22: CUST013 | F22: PROD015 | G22: Central | H22: 21 | I22: 4 | J22: 84 | K22: PayPal | L22: In Transit | M22: Amazon Logistics
A23: ORD0022 | B23: 11/9/2023 | E23: CUST023 | F23: PROD012 | G23: West | H23: 46 | I23: 5 | J23: 230 | K23: PayPal | L23: In Transit | M23: USPS
A24: ORD0023 | B24: 2/13/2023 | D24: 2/14/2023 | E24: CUST016 | F24: PROD010 | G24: West | H24: 58 | I24: 3 | J24: 174 | K24: Amazon Pay | L24: Cancelled | M24: Amazon Logistics
A25: ORD0024 | B25: 11/2/2023 | C25: 11/5/2023 | E25: CUST028 | F25: PROD006 | G25: West | H25: 96 | I25: 5 | J25: 480 | K25: Amazon Pay | L25: Delivered | M25: Amazon Logistics
A26: ORD0025 | B26: 5/28/2023 | C26: 5/30/2023 | E26: CUST040 | F26: PROD002 | G26: South | H26: 43 | I26: 1 | J26: 43 | K26: Debit Card | L26: Delivered | M26: Amazon Logistics
A27: ORD0026 | B27: 10/15/2023 | C27: 10/21/2023 | E27: CUST027 | F27: PROD022 | G27: South | H27: 64 | I27: 4 | J27: 256 | K27: Debit Card | L27: Delivered | M27: USPS
A28: ORD0027 | B28: 1/16/2023 | E28: CUST018 | F28: PROD008 | G28: South | H28: 70 | I28: 2 | J28: 140 | K28: Amazon Pay | L28: In Transit | M28: Amazon Logistics
A29: ORD0028 | B29: 10/9/2023 | E29: CUST018 | F29: PROD018 | G29: Central | H29: 97 | I29: 3 | J29: 291 | K29: Credit Card | L29: In Transit | M29: Amazon Logistics
A30: ORD0029 | B30: 10/7/2023 | D30: 10/10/2023 | E30: CUST007 | F30: PROD021 | G30: East | H30: 37 | I30: 3 | J30: 111 | K30: Apple Pay | L30: Cancelled | M30: DHL
A31: ORD0030 | B31: 2/14/2023 | E31: CUST008 | F31: PROD008 | G31: North | H31: 69 | I31: 5 | J31: 345 | K31: Amazon Pay | L31: In Transit | M31: Amazon Logistics
A32: ORD0031 | B32: 3/26/2023 | E32: CUST014 | F32: PROD002 | G32: North | H32: 42 | I32: 5 | J32: 210 | K32: Amazon Pay | L32: In Transit | M32: UPS
A33: ORD0032 | B33: 6/15/2023 | D33: 6/22/2023 | E33: CUST037 | F33: PROD009 | G33: East | H33: 11 | I33: 5 | J33: 55 | K33: Debit Card | L33: Cancelled | M33: FedEx
A34: ORD0033 | B34: 5/22/2023 | C34: 5/23/2023 | E34: CUST016 | F34: PROD005 | G34: South | H34: 27 | I34: 2 | J34: 54 | K34: Apple Pay | L34: Delivered | M34: USPS
A35: ORD0034 | B35: 11/20/2023 | E35: CUST025 | F35: PROD015 | G35: South | H35: 21 | I35: 1 | J35: 21 | K35: Amazon Pay | L35: In Transit | M35: DHL
A36: ORD0035 | B36: 12/22/2023 | C36: 12/26/2023 | E36: CUST032 | F36: PROD011 | G36: South | H36: 172 | I36: 1 | J36: 172 | K36: PayPal | L36: Delivered | M36: USPS
A37: ORD0036 | B37: 7/23/2023 | E37: CUST014 | F37: PROD016 | G37: North | H37: 212 | I37: 3 | J37: 636 | K37: Amazon Pay | L37: In Transit | M37: UPS
A38: ORD0037 | B38: 10/17/2023 | C38: 10/22/2023 | E38: CUST044 | F38: PROD002 | G38: East | H38: 41 | I38: 4 | J38: 164 | K38: Credit Card | L38: Delivered | M38: Amazon Logistics
A39: ORD0038 | B39: 8/22/2023 | D39: 8/24/2023 | E39: CUST028 | F39: PROD007 | G39: North | H39: 32 | I39: 2 | J39: 64 | K39: Debit Card | L39: Cancelled | M39: FedEx
A40: ORD0039 | B40: 12/2/2023 | E40: CUST024 | F40: PROD022 | G40: East | H40: 66 | I40: 2 | J40: 132 | K40: Apple Pay | L40: In Transit | M40: DHL
...

Sheet ProductMaster
A1: Product ID | B1: Product Name | C1: Category | D1: Cost Price | E1: Description
A2: PROD001 | B2: Smartphone | C2: Electronics | D2: 749 | E2: Latest model with 5G, dual SIM, and OLED display
A3: PROD002 | B3: Action Figure | C3: Toys | D3: 39 | E3: Collectible superhero action figure for ages 8+
A4: PROD003 | B4: Cookware Set | C4: Home | D4: 129 | E4: Non-stick 5-piece cookware set for daily use
A5: PROD004 | B5: Leg Set | C5: Toys | D5: 59 | E5: 300-piece creative building block toy set
A6: PROD005 | B6: T-Shirt | C6: Fashion | D6: 25 | E6: Cotton t-shirt, available in multiple colors
A7: PROD006 | B7: Shoes | C7: Fashion | D7: 89 | E7: Casual wear shoes for men and women
A8: PROD007 | B8: Puzzle | C8: Toys | D8: 29 | E8: 1000-piece jigsaw puzzle
A9: PROD008 | B9: Textbook | C9: Books | D9: 65 | E9: University-level textbook on computer science
A10: PROD009 | B10: Magazine | C10: Books | D10: 10 | E10: Monthly lifestyle magazine
A11: PROD010 | B11: Jeans | C11: Fashion | D11: 55 | E11: Slim fit denim jeans with stretch
A12: PROD011 | B12: Headphones | C12: Electronics | D12: 159 | E12: Wireless noise-cancelling over-ear headphones
A13: PROD012 | B13: Lamp | C13: Home | D13: 42 | E13: LED desk lamp with dimmable light
... A23: PROD022 | B23: Backpack | C23: Fashion | D23: 60 | E23: Waterproof backpack with laptop compartment
A24: Total | B24: =SUBTOTAL(103,Product_table[Product Name]) -> 22 | E24: =SUBTOTAL(103,Product_table[Description]) -> 22

Sheet RegionGoals
A1: Region | B1: Sales Target
A2: Central | B2: 97500
A3: East | B3: 50500
A4: North | B4: 105000
A5: South | B5: 91500
A6: West | B6: 90750

Sheet CustomerMaster
A1: Customer ID | B1: Customer Name | C1: Customer Type | D1: City | E1: State
A2: CUST001 | B2: James Miller | C2: Business | D2: New York | E2: New York
A3: CUST002 | B3: Emily Johnson | C3: Prime | D3: Seattle | E3: Washington
A4: CUST003 | B4: Ethan Davis | C4: Prime | D4: Austin | E4: Texas
A5: CUST004 | B5: Noah Wilson | C5: Prime | D5: San Francisco | E5: California
A6: CUST005 | B6: Olivia Martinez | C6: Prime | D6: Seattle | E6: Washington
A7: CUST006 | B7: Ava Robinson | C7: Prime | D7: Chicago | E7: Illinois
A8: CUST007 | B8: Liam Walker | C8: Prime | D8: San Francisco | E8: California
A9: CUST008 | B9: Harper Young | C9: Business | D9: Dallas | E9: Texas
A10: CUST009 | B10: Jackson Allen | C10: Business | D10: Seattle | E10: Washington
A11: CUST010 | B11: Charlotte Harris | C11: Prime | D11: Chicago | E11: Illinois
A12: CUST011 | B12: Mason Hall | C12: Business | D12: Miami | E12: Florida
... A50: CUST049 | B50: Hazel Gray | C50: Business | D50: Chicago | E50: Illinois

Sheet Task1
A1: Order count | B1: Order ID | C1: Order Date | D1: Delivery Date | E1: Cancel Date | F1: Customer ID | G1: Product ID | H1: Product Category | I1: Product Name | J1: Region | K1: Sale Price/Unit | L1: Quantity | M1: Total Amount | N1: Payment Method | O1: Delivery Status | P1: Fulfillment Partner | Q1: Order Status | R1: Delivery Time | S1: Cancelled | T1: Delivered | U1: Delivered sales Amount | V1: Delivery performance | W1: Fast delivery
A2: 1 | B2: ORD0001 | C2: 45291 | E2: 45323 | F2: CUST021 | G2: PROD012 | H2: =_xlfn.XLOOKUP(AmazonSales[[#This Row],[Product ID]],Product_table[Product ID],Product_table[Category]) -> Home | I2: =_xlfn.XLOOKUP(AmazonSales[[#This Row],[Product ID]],Product_table[Product ID],Product_table[Product Name]) -> Lamp | J2: North | K2: 44 | L2: 1 | M2: 44 | N2: Apple Pay | O2: Cancelled | P2: DHL | Q2: =IF(AND(E2<>"", O2="Cancelled"), "Cancelled", "Active") -> Cancelled | S2: =IF(AmazonSales[[#This Row],[Order Status]]="Cancelled",1,0) -> 1 | T2: =IF(AmazonSales[[#This Row],[Delivery Status]]="Delivered",1,0) -> 0 | U2: =IF(AmazonSales[[#This Row],[Delivery Status]]="Delivered",AmazonSales[[#This Row],[Total Amount]],0) -> 0 | V2: {=_xlfn.IFS(AND(AmazonSales[[#This Row],[Delivery Time]]=""),"",AND(AmazonSales[[#This Row],[Delivery Time]]<=2),"Fast",AND(AmazonSales[[#This Row],[Delivery Time]]>2),"Slow")} | W2: =IF(AmazonSales[[#This Row],[Delivery performance]]="Fast",1,0) -> 0
A3: 1 | B3: ORD0002 | C3: 44979 | D3: 44981 | F3: CUST029 | G3: PROD018 | H3: =_xlfn.XLOOKUP(AmazonSales[[#This Row],[Product ID]],Product_table[Product ID],Product_table[Category]) -> Toys | I3: =_xlfn.XLOOKUP(AmazonSales[[#This Row],[Product ID]],Product_table[Product ID],Product_table[Product Name]) -> Doll House | J3: East | K3: 96 | L3: 4 | M3: 384 | N3: Credit Card | O3: Delivered | P3: DHL | Q3: =IF(AND(E3<>"", O3="Cancelled"), "Cancelled", "Active") -> Active | R3: =DATEDIF(AmazonSales[[#This Row],[Order Date]],AmazonSales[[#This Row],[Delivery Date]],"d") -> 2 | S3: =IF(AmazonSales[[#This Row],[Order Status]]="Cancelled",1,0) -> 0 | T3: =IF(AmazonSales[[#This Row],[Delivery Status]]="Delivered",1,0) -> 1 | U3: =IF(AmazonSales[[#This Row],[Delivery Status]]="Delivered",AmazonSales[[#This Row],[Total Amount]],0) -> 384 | V3: {=_xlfn.IFS(AND(AmazonSales[[#This Row],[Delivery Time]]=""),"",AND(AmazonSales[[#This Row],[Delivery Time]]<=2),"Fast",AND(AmazonSales[[#This Row],[Delivery Time]]>2),"Slow")} -> Fast | W3: =IF(AmazonSales[[#This Row],[Delivery performance]]="Fast",1,0) -> 1
A4: 1 | B4: ORD0003 | C4: 45240 | F4: CUST021 | G4: PROD013 | H4: =_xlfn.XLOOKUP(AmazonSales[[#This Row],[Product ID]],Product_table[Product ID],Product_table[Category]) -> Home | I4: =_xlfn.XLOOKUP(AmazonSales[[#This Row],[Product ID]],Product_table[Product ID],Product_table[Product Name]) -> Vacuum Cleaner | J4: South | K4: 194 | L4: 4 | M4: 776 | N4: Credit Card | O4: In Transit | P4: USPS | Q4: =IF(AND(E4<>"", O4="Cancelled"), "Cancelled", "Active") -> Active | S4: =IF(AmazonSales[[#This Row],[Order Status]]="Cancelled",1,0) -> 0 | T4: =IF(AmazonSales[[#This Row],[Delivery Status]]="Delivered",1,0) -> 0 | U4: =IF(AmazonSales[[#This Row],[Delivery Status]]="Delivered",AmazonSales[[#This Row],[Total Amount]],0) -> 0 | V4: {=_xlfn.IFS(AND(AmazonSales[[#This Row],[Delivery Time]]=""),"",AND(AmazonSales[[#This Row],[Delivery Time]]<=2),"Fast",AND(AmazonSales[[#This Row],[Delivery Time]]>2),"Slow")} | W4: =IF(AmazonSales[[#This Row],[Delivery performance]]="Fast",1,0) -> 0
A5: 1 | B5: ORD0004 | C5: 45051 | E5: 45235 | F5: CUST044 | G5: PROD013 | H5: =_xlfn.XLOOKUP(AmazonSales[[#This Row],[Product ID]],Product_table[Product ID],Product_table[Category]) -> Home | I5: =_xlfn.XLOOKUP(AmazonSales[[#This Row],[Product ID]],Product_table[Product ID],Product_table[Product Name]) -> Vacuum Cleaner | J5: North | K5: 196 | L5: 3 | M5: 588 | N5: PayPal | O5: Cancelled | P5: UPS | Q5: =IF(AND(E5<>"", O5="Cancelled"), "Cancelled", "Active") -> Cancelled | S5: =IF(AmazonSales[[#This Row],[Order Status]]="Cancelled",1,0) -> 1 | T5: =IF(AmazonSales[[#This Row],[Delivery Status]]="Delivered",1,0) -> 0 | U5: =IF(AmazonSales[[#This Row],[Delivery Status]]="Delivered",AmazonSales[[#This Row],[Total Amount]],0) -> 0 | V5: {=_xlfn.IFS(AND(AmazonSales[[#This Row],[Delivery Time]]=""),"",AND(AmazonSales[[#This Row],[Delivery Time]]<=2),"Fast",AND(AmazonSales[[#This Row],[Delivery Time]]>2),"Slow")} | W5: =IF(AmazonSales[[#This Row],[Delivery performance]]="Fast",1,0) -> 0
A6: 1 | B6: ORD0005 | C6: 44959 | D6: 44962 | F6: CUST027 | G6: PROD010 | H6: =_xlfn.XLOOKUP(AmazonSales[[#This Row],[Product ID]],Product_table[Product ID],Product_table[Category]) -> Fashion | I6: =_xlfn.XLOOKUP(AmazonSales[[#This Row],[Product ID]],Product_table[Product ID],Product_table[Product Name]) -> Jeans | J6: North | K6: 59 | L6: 1 | M6: 59 | N6: PayPal | O6: Delivered | P6: Amazon Logistics | Q6: =IF(AND(E6<>"", O6="Cancelled"), "Cancelled", "Active") -> Active | R6: =DATEDIF(AmazonSales[[#This Row],[Order Date]],AmazonSales[[#This Row],[Delivery Date]],"d") -> 3 | S6: =IF(AmazonSales[[#This Row],[Order Status]]="Cancelled",1,0) -> 0 | T6: =IF(AmazonSales[[#This Row],[Delivery Status]]="Delivered",1,0) -> 1 | U6: =IF(AmazonSales[[#This Row],[Delivery Status]]="Delivered",AmazonSales[[#This Row],[Total Amount]],0) -> 59 | V6: {=_xlfn.IFS(AND(AmazonSales[[#This Row],[Delivery Time]]=""),"",AND(AmazonSales[[#This Row],[Delivery Time]]<=2),"Fast",AND(AmazonSales[[#This Row],[Delivery Time]]>2),"Slow")} -> Slow | W6: =IF(AmazonSales[[#This Row],[Delivery performance]]="Fast",1,0) -> 0
A7: 1 | B7: ORD0006 | C7: 44937 | E7: 44968 | F7: CUST009 | G7: PROD010 | H7: =_xlfn.XLOOKUP(AmazonSales[[#This Row],[Product ID]],Product_table[Product ID],Product_table[Category]) -> Fashion | I7: =_xlfn.XLOOKUP(AmazonSales[[#This Row],[Product ID]],Product_table[Product ID],Product_table[Product Name]) -> Jeans | J7: North | K7: 58 | L7: 4 | M7: 232 | N7: Amazon Pay | O7: Cancelled | P7: DHL | Q7: =IF(AND(E7<>"", O7="Cancelled"), "Cancelled", "Active") -> Cancelled | S7: =IF(AmazonSales[[#This Row],[Order Status]]="Cancelled",1,0) -> 1 | T7: =IF(AmazonSales[[#This Row],[Delivery Status]]="Delivered",1,0) -> 0 | U7: =IF(AmazonSales[[#This Row],[Delivery Status]]="Delivered",AmazonSales[[#This Row],[Total Amount]],0) -> 0 | V7: {=_xlfn.IFS(AND(AmazonSales[[#This Row],[Delivery Time]]=""),"",AND(AmazonSales[[#This Row],[Delivery Time]]<=2),"Fast",AND(AmazonSales[[#This Row],[Delivery Time]]>2),"Slow")} | W7: =IF(AmazonSales[[#This Row],[Delivery performance]]="Fast",1,0) -> 0
A8: 1 | B8: ORD0007 | C8: 45152 | E8: 45156 | F8: CUST042 | G8: PROD020 | H8: =_xlfn.XLOOKUP(AmazonSales[[#This Row],[Product ID]],Product_table[Product ID],Product_table[Category]) -> Electronics | I8: =_xlfn.XLOOKUP(AmazonSales[[#This Row],[Product ID]],Product_table[Product ID],Product_table[Product Name]) -> Bluetooth Speaker | J8: Central | K8: 105 | L8: 3 | M8: 315 | N8: Debit Card | O8: Cancelled | P8: DHL | Q8: =IF(AND(E8<>"", O8="Cancelled"), "Cancelled", "Active") -> Cancelled | S8: =IF(AmazonSales[[#This Row],[Order Status]]="Cancelled",1,0) -> 1 | T8: =IF(AmazonSales[[#This Row],[Delivery Status]]="Delivered",1,0) -> 0 | U8: =IF(AmazonSales[[#This Row],[Delivery Status]]="Delivered",AmazonSales[[#This Row],[Total Amount]],0) -> 0 | V8: {=_xlfn.IFS(AND(AmazonSales[[#This Row],[Delivery Time]]=""),"",AND(AmazonSales[[#This Row],[Delivery Time]]<=2),"Fast",AND(AmazonSales[[#This Row],[Delivery Time]]>2),"Slow")} | W8: =IF(AmazonSales[[#This Row],[Delivery performance]]="Fast",1,0) -> 0
A9: 1 | B9: ORD0008 | C9: 44930 | E9: 45081 | F9: CUST019 | G9: PROD021 | H9: =_xlfn.XLOOKUP(AmazonSales[[#This Row],[Product ID]],Product_table[Product ID],Product_table[Category]) -> Home | I9: =_xlfn.XLOOKUP(AmazonSales[[#This Row],[Product ID]],Product_table[Product ID],Product_table[Product Name]) -> Wall Clock | J9: West | K9: 37 | L9: 5 | M9: 185 | N9: PayPal | O9: Cancelled | P9: DHL | Q9: =IF(AND(E9<>"", O9="Cancelled"), "Cancelled", "Active") -> Cancelled | S9: =IF(AmazonSales[[#This Row],[Order Status]]="Cancelled",1,0) -> 1 | T9: =IF(AmazonSales[[#This Row],[Delivery Status]]="Delivered",1,0) -> 0 | U9: =IF(AmazonSales[[#This Row],[Delivery Status]]="Delivered",AmazonSales[[#This Row],[Total Amount]],0) -> 0 | V9: {=_xlfn.IFS(AND(AmazonSales[[#This Row],[Delivery Time]]=""),"",AND(AmazonSales[[#This Row],[Delivery Time]]<=2),"Fast",AND(AmazonSales[[#This Row],[Delivery Time]]>2),"Slow")} | W9: =IF(AmazonSales[[#This Row],[Delivery performance]]="Fast",1,0) -> 0
A10: 1 | B10: ORD0009 | C10: 45128 | F10: CUST013 | G10: PROD019 | H10: =_xlfn.XLOOKUP(AmazonSales[[#This Row],[Product ID]],Product_table[Product ID],Product_table[Category]) -> Fashion | I10: =_xlfn.XLOOKUP(AmazonSales[[#This Row],[Product ID]],Product_table[Product ID],Product_table[Product Name]) -> Formal Shirt | J10: Central | K10: 44 | L10: 2 | M10: 88 | N10: Credit Card | O10: In Transit | P10: Amazon Logistics | Q10: =IF(AND(E10<>"", O10="Cancelled"), "Cancelled", "Active") -> Active | S10: =IF(AmazonSales[[#This Row],[Order Status]]="Cancelled",1,0) -> 0 | T10: =IF(AmazonSales[[#This Row],[Delivery Status]]="Delivered",1,0) -> 0 | U10: =IF(AmazonSales[[#This Row],[Delivery Status]]="Delivered",AmazonSales[[#This Row],[Total Amount]],0) -> 0 | V10: {=_xlfn.IFS(AND(AmazonSales[[#This Row],[Delivery Time]]=""),"",AND(AmazonSales[[#This Row],[Delivery Time]]<=2),"Fast",AND(AmazonSales[[#This Row],[Delivery Time]]>2),"Slow")} | W10: =IF(AmazonSales[[#This Row],[Delivery performance]]="Fast",1,0) -> 0
A11: 1 | B11: ORD0010 | C11: 45289 | F11: CUST019 | G11: PROD003 | H11: =_xlfn.XLOOKUP(AmazonSales[[#This Row],[Product ID]],Product_table[Product ID],Product_table[Category]) -> Home | I11: =_xlfn.XLOOKUP(AmazonSales[[#This Row],[Product ID]],Product_table[Product ID],Product_table[Product Name]) -> Cookware Set | J11: South | K11: 141 | L11: 4 | M11: 564 | N11: Debit Card | O11: In Transit | P11: DHL | Q11: =IF(AND(E11<>"", O11="Cancelled"), "Cancelled", "Active") -> Active | S11: =IF(AmazonSales[[#This Row],[Order Status]]="Cancelled",1,0) -> 0 | T11: =IF(AmazonSales[[#This Row],[Delivery Status]]="Delivered",1,0) -> 0 | U11: =IF(AmazonSales[[#This Row],[Delivery Status]]="Delivered",AmazonSales[[#This Row],[Total Amount]],0) -> 0 | V11: {=_xlfn.IFS(AND(AmazonSales[[#This Row],[Delivery Time]]=""),"",AND(AmazonSales[[#This Row],[Delivery Time]]<=2),"Fast",AND(AmazonSales[[#This Row],[Delivery Time]]>2),"Slow")} | W11: =IF(AmazonSales[[#This Row],[Delivery performance]]="Fast",1,0) -> 0
A12: 1 | B12: ORD0011 | C12: 45021 | E12: 45143 | F12: CUST046 | G12: PROD014 | H12: =_xlfn.XLOOKUP(AmazonSales[[#This Row],[Product ID]],Product_table[Product ID],Product_table[Category]) -> Electronics | I12: =_xlfn.XLOOKUP(AmazonSales[[#This Row],[Product ID]],Product_table[Product ID],Product_table[Product Name]) -> Smartwatch | J12: South | K12: 249 | L12: 1 | M12: 249 | N12: Amazon Pay | O12: Cancelled | P12: USPS | Q12: =IF(AND(E12<>"", O12="Cancelled"), "Cancelled", "Active") -> Cancelled | S12: =IF(AmazonSales[[#This Row],[Order Status]]="Cancelled",1,0) -> 1 | T12: =IF(AmazonSales[[#This Row],[Delivery Status]]="Delivered",1,0) -> 0 | U12: =IF(AmazonSales[[#This Row],[Delivery Status]]="Delivered",AmazonSales[[#This Row],[Total Amount]],0) -> 0 | V12: {=_xlfn.IFS(AND(AmazonSales[[#This Row],[Delivery Time]]=""),"",AND(AmazonSales[[#This Row],[Delivery Time]]<=2),"Fast",AND(AmazonSales[[#This Row],[Delivery Time]]>2),"Slow")} | W12: =IF(AmazonSales[[#This Row],[Delivery performance]]="Fast",1,0) -> 0
A13: 1 | B13: ORD0012 | C13: 45132 | F13: CUST045 | G13: PROD014 | H13: =_xlfn.XLOOKUP(AmazonSales[[#This Row],[Product ID]],Product_table[Product ID],Product_table[Category]) -> Electronics | I13: =_xlfn.XLOOKUP(AmazonSales[[#This Row],[Product ID]],Product_table[Product ID],Product_table[Product Name]) -> Smartwatch | J13: Central | K13: 247 | L13: 3 | M13: 741 | N13: Amazon Pay | O13: In Transit | P13: FedEx | Q13: =IF(AND(E13<>"", O13="Cancelled"), "Cancelled", "Active") -> Active | S13: =IF(AmazonSales[[#This Row],[Order Status]]="Cancelled",1,0) -> 0 | T13: =IF(AmazonSales[[#This Row],[Delivery Status]]="Delivered",1,0) -> 0 | U13: =IF(AmazonSales[[#This Row],[Delivery Status]]="Delivered",AmazonSales[[#This Row],[Total Amount]],0) -> 0 | V13: {=_xlfn.IFS(AND(AmazonSales[[#This Row],[Delivery Time]]=""),"",AND(AmazonSales[[#This Row],[Delivery Time]]<=2),"Fast",AND(AmazonSales[[#This Row],[Delivery Time]]>2),"Slow")} | W13: =IF(AmazonSales[[#This Row],[Delivery performance]]="Fast",1,0) -> 0
A14: 1 | B14: ORD0013 | C14: 44982 | E14: 44985 | F14: CUST023 | G14: PROD006 | H14: =_xlfn.XLOOKUP(AmazonSales[[#This Row],[Product ID]],Product_table[Product ID],Product_table[Category]) -> Fashion | I14: =_xlfn.XLOOKUP(AmazonSales[[#This Row],[Product ID]],Product_table[Product ID],Product_table[Product Name]) -> Shoes | J14: Central | K14: 96 | L14: 1 | M14: 96 | N14: Apple Pay | O14: Cancelled | P14: Amazon Logistics | Q14: =IF(AND(E14<>"", O14="Cancelled"), "Cancelled", "Active") -> Cancelled | S14: =IF(AmazonSales[[#This Row],[Order Status]]="Cancelled",1,0) -> 1 | T14: =IF(AmazonSales[[#This Row],[Delivery Status]]="Delivered",1,0) -> 0 | U14: =IF(AmazonSales[[#This Row],[Delivery Status]]="Delivered",AmazonSales[[#This Row],[Total Amount]],0) -> 0 | V14: {=_xlfn.IFS(AND(AmazonSales[[#This Row],[Delivery Time]]=""),"",AND(AmazonSales[[#This Row],[Delivery Time]]<=2),"Fast",AND(AmazonSales[[#This Row],[Delivery Time]]>2),"Slow")} | W14: =IF(AmazonSales[[#This Row],[Delivery performance]]="Fast",1,0) -> 0
A15: 1 | B15: ORD0014 | C15: 44981 | E15: 44982 | F15: CUST033 | G15: PROD017 | H15: =_xlfn.XLOOKUP(AmazonSales[[#This Row],[Product ID]],Product_table[Product ID],Product_table[Category]) -> Electronics | I15: =_xlfn.XLOOKUP(AmazonSales[[#This Row],[Product ID]],Product_table[Product ID],Product_table[Product Name]) -> Gaming Mouse | J15: West | K15: 74 | L15: 5 | M15: 370 | N15: Apple Pay | O15: Cancelled | P15: Amazon Logistics | Q15: =IF(AND(E15<>"", O15="Cancelled"), "Cancelled", "Active") -> Cancelled | S15: =IF(AmazonSales[[#This Row],[Order Status]]="Cancelled",1,0) -> 1 | T15: =IF(AmazonSales[[#This Row],[Delivery Status]]="Delivered",1,0) -> 0 | U15: =IF(AmazonSales[[#This Row],[Delivery Status]]="Delivered",AmazonSales[[#This Row],[Total Amount]],0) -> 0 | V15: {=_xlfn.IFS(AND(AmazonSales[[#This Row],[Delivery Time]]=""),"",AND(AmazonSales[[#This Row],[Delivery Time]]<=2),"Fast",AND(AmazonSales[[#This Row],[Delivery Time]]>2),"Slow")} | W15: =IF(AmazonSales[[#This Row],[Delivery performance]]="Fast",1,0) -> 0
A16: 1 | B16: ORD0015 | C16: 45164 | E16: 45171 | F16: CUST033 | G16: PROD005 | H16: =_xlfn.XLOOKUP(AmazonSales[[#This Row],[Product ID]],Product_table[Product ID],Product_table[Category]) -> Fashion | I16: =_xlfn.XLOOKUP(AmazonSales[[#This Row],[Product ID]],Product_table[Product ID],Product_table[Product Name]) -> T-Shirt | J16: South | K16: 27 | L16: 1 | M16: 27 | N16: Credit Card | O16: Cancelled | P16: Amazon Logistics | Q16: =IF(AND(E16<>"", O16="Cancelled"), "Cancelled", "Active") -> Cancelled | S16: =IF(AmazonSales[[#This Row],[Order Status]]="Cancelled",1,0) -> 1 | T16: =IF(AmazonSales[[#This Row],[Delivery Status]]="Delivered",1,0) -> 0 | U16: =IF(AmazonSales[[#This Row],[Delivery Status]]="Delivered",AmazonSales[[#This Row],[Total Amount]],0) -> 0 | V16: {=_xlfn.IFS(AND(AmazonSales[[#This Row],[Delivery Time]]=""),"",AND(AmazonSales[[#This Row],[Delivery Time]]<=2),"Fast",AND(AmazonSales[[#This Row],[Delivery Time]]>2),"Slow")} | W16: =IF(AmazonSales[[#This Row],[Delivery performance]]="Fast",1,0) -> 0
A17: 1 | B17: ORD0016 | C17: 44970 | F17: CUST047 | G17: PROD005 | H17: =_xlfn.XLOOKUP(AmazonSales[[#This Row],[Product ID]],Product_table[Product ID],Product_table[Category]) -> Fashion | I17: =_xlfn.XLOOKUP(AmazonSales[[#This Row],[Product ID]],Product_table[Product ID],Product_table[Product Name]) -> T-Shirt | J17: South | K17: 27 | L17: 3 | M17: 81 | N17: Debit Card | O17: In Transit | P17: Amazon Logistics | Q17: =IF(AND(E17<>"", O17="Cancelled"), "Cancelled", "Active") -> Active | S17: =IF(AmazonSales[[#This Row],[Order Status]]="Cancelled",1,0) -> 0 | T17: =IF(AmazonSales[[#This Row],[Delivery Status]]="Delivered",1,0) -> 0 | U17: =IF(AmazonSales[[#This Row],[Delivery Status]]="Delivered",AmazonSales[[#This Row],[Total Amount]],0) -> 0 | V17: {=_xlfn.IFS(AND(AmazonSales[[#This Row],[Delivery Time]]=""),"",AND(AmazonSales[[#This Row],[Delivery Time]]<=2),"Fast",AND(AmazonSales[[#This Row],[Delivery Time]]>2),"Slow")} | W17: =IF(AmazonSales[[#This Row],[Delivery performance]]="Fast",1,0) -> 0
A18: 1 | B18: ORD0017 | C18: 45105 | D18: 45108 | F18: CUST045 | G18: PROD015 | H18: =_xlfn.XLOOKUP(AmazonSales[[#This Row],[Product ID]],Product_table[Product ID],Product_table[Category]) -> Books | I18: =_xlfn.XLOOKUP(AmazonSales[[#This Row],[Product ID]],Product_table[Product ID],Product_table[Product Name]) -> Novel | J18: East | K18: 21 | L18: 3 | M18: 63 | N18: Credit Card | O18: Delivered | P18: DHL | Q18: =IF(AND(E18<>"", O18="Cancelled"), "Cancelled", "Active") -> Active | R18: =DATEDIF(AmazonSales[[#This Row],[Order Date]],AmazonSales[[#This Row],[Delivery Date]],"d") -> 3 | S18: =IF(AmazonSales[[#This Row],[Order Status]]="Cancelled",1,0) -> 0 | T18: =IF(AmazonSales[[#This Row],[Delivery Status]]="Delivered",1,0) -> 1 | U18: =IF(AmazonSales[[#This Row],[Delivery Status]]="Delivered",AmazonSales[[#This Row],[Total Amount]],0) -> 63 | V18: {=_xlfn.IFS(AND(AmazonSales[[#This Row],[Delivery Time]]=""),"",AND(AmazonSales[[#This Row],[Delivery Time]]<=2),"Fast",AND(AmazonSales[[#This Row],[Delivery Time]]>2),"Slow")} -> Slow | W18: =IF(AmazonSales[[#This Row],[Delivery performance]]="Fast",1,0) -> 0
A19: 1 | B19: ORD0018 | C19: 45258 | F19: CUST011 | G19: PROD008 | H19: =_xlfn.XLOOKUP(AmazonSales[[#This Row],[Product ID]],Product_table[Product ID],Product_table[Category]) -> Books | I19: =_xlfn.XLOOKUP(AmazonSales[[#This Row],[Product ID]],Product_table[Product ID],Product_table[Product Name]) -> Textbook | J19: West | K19: 70 | L19: 5 | M19: 350 | N19: PayPal | O19: In Transit | P19: Amazon Logistics | Q19: =IF(AND(E19<>"", O19="Cancelled"), "Cancelled", "Active") -> Active | S19: =IF(AmazonSales[[#This Row],[Order Status]]="Cancelled",1,0) -> 0 | T19: =IF(AmazonSales[[#This Row],[Delivery Status]]="Delivered",1,0) -> 0 | U19: =IF(AmazonSales[[#This Row],[Delivery Status]]="Delivered",AmazonSales[[#This Row],[Total Amount]],0) -> 0 | V19: {=_xlfn.IFS(AND(AmazonSales[[#This Row],[Delivery Time]]=""),"",AND(AmazonSales[[#This Row],[Delivery Time]]<=2),"Fast",AND(AmazonSales[[#This Row],[Delivery Time]]>2),"Slow")} | W19: =IF(AmazonSales[[#This Row],[Delivery performance]]="Fast",1,0) -> 0
A20: 1 | B20: ORD0019 | C20: 45163 | F20: CUST041 | G20: PROD006 | H20: =_xlfn.XLOOKUP(AmazonSales[[#This Row],[Product ID]],Product_table[Product ID],Product_table[Category]) -> Fashion | I20: =_xlfn.XLOOKUP(AmazonSales[[#This Row],[Product ID]],Product_table[Product ID],Product_table[Product Name]) -> Shoes | J20: South | K20: 94 | L20: 4 | M20: 376 | N20: Credit Card | O20: In Transit | P20: USPS | Q20: =IF(AND(E20<>"", O20="Cancelled"), "Cancelled", "Active") -> Active | S20: =IF(AmazonSales[[#This Row],[Order Status]]="Cancelled",1,0) -> 0 | T20: =IF(AmazonSales[[#This Row],[Delivery Status]]="Delivered",1,0) -> 0 | U20: =IF(AmazonSales[[#This Row],[Delivery Status]]="Delivered",AmazonSales[[#This Row],[Total Amount]],0) -> 0 | V20: {=_xlfn.IFS(AND(AmazonSales[[#This Row],[Delivery Time]]=""),"",AND(AmazonSales[[#This Row],[Delivery Time]]<=2),"Fast",AND(AmazonSales[[#This Row],[Delivery Time]]>2),"Slow")} | W20: =IF(AmazonSales[[#This Row],[Delivery performance]]="Fast",1,0) -> 0
A21: 1 | B21: ORD0020 | C21: 45264 | F21: CUST025 | G21: PROD001 | H21: =_xlfn.XLOOKUP(AmazonSales[[#This Row],[Product ID]],Product_table[Product ID],Product_table[Category]) -> Electronics | I21: =_xlfn.XLOOKUP(AmazonSales[[#This Row],[Product ID]],Product_table[Product ID],Product_table[Product Name]) -> Smartphone | J21: North | K21: 813 | L21: 2 | M21: 1626 | N21: Credit Card | O21: In Transit | P21: FedEx | Q21: =IF(AND(E21<>"", O21="Cancelled"), "Cancelled", "Active") -> Active | S21: =IF(AmazonSales[[#This Row],[Order Status]]="Cancelled",1,0) -> 0 | T21: =IF(AmazonSales[[#This Row],[Delivery Status]]="Delivered",1,0) -> 0 | U21: =IF(AmazonSales[[#This Row],[Delivery Status]]="Delivered",AmazonSales[[#This Row],[Total Amount]],0) -> 0 | V21: {=_xlfn.IFS(AND(AmazonSales[[#This Row],[Delivery Time]]=""),"",AND(AmazonSales[[#This Row],[Delivery Time]]<=2),"Fast",AND(AmazonSales[[#This Row],[Delivery Time]]>2),"Slow")} | W21: =IF(AmazonSales[[#This Row],[Delivery performance]]="Fast",1,0) -> 0
A22: 1 | B22: ORD0021 | C22: 44967 | F22: CUST013 | G22: PROD015 | H22: =_xlfn.XLOOKUP(AmazonSales[[#This Row],[Product ID]],Product_table[Product ID],Product_table[Category]) -> Books | I22: =_xlfn.XLOOKUP(AmazonSales[[#This Row],[Product ID]],Product_table[Product ID],Product_table[Product Name]) -> Novel | J22: Central | K22: 21 | L22: 4 | M22: 84 | N22: PayPal | O22: In Transit | P22: Amazon Logistics | Q22: =IF(AND(E22<>"", O22="Cancelled"), "Cancelled", "Active") -> Active | S22: =IF(AmazonSales[[#This Row],[Order Status]]="Cancelled",1,0) -> 0 | T22: =IF(AmazonSales[[#This Row],[Delivery Status]]="Delivered",1,0) -> 0 | U22: =IF(AmazonSales[[#This Row],[Delivery Status]]="Delivered",AmazonSales[[#This Row],[Total Amount]],0) -> 0 | V22: {=_xlfn.IFS(AND(AmazonSales[[#This Row],[Delivery Time]]=""),"",AND(AmazonSales[[#This Row],[Delivery Time]]<=2),"Fast",AND(AmazonSales[[#This Row],[Delivery Time]]>2),"Slow")} | W22: =IF(AmazonSales[[#This Row],[Delivery performance]]="Fast",1,0) -> 0
A23: 1 | B23: ORD0022 | C23: 45180 | F23: CUST023 | G23: PROD012 | H23: =_xlfn.XLOOKUP(AmazonSales[[#This Row],[Product ID]],Product_table[Product ID],Product_table[Category]) -> Home | I23: =_xlfn.XLOOKUP(AmazonSales[[#This Row],[Product ID]],Product_table[Product ID],Product_table[Product Name]) -> Lamp | J23: West | K23: 46 | L23: 5 | M23: 230 | N23: PayPal | O23: In Transit | P23: USPS | Q23: =IF(AND(E23<>"", O23="Cancelled"), "Cancelled", "Active") -> Active | S23: =IF(AmazonSales[[#This Row],[Order Status]]="Cancelled",1,0) -> 0 | T23: =IF(AmazonSales[[#This Row],[Delivery Status]]="Delivered",1,0) -> 0 | U23: =IF(AmazonSales[[#This Row],[Delivery Status]]="Delivered",AmazonSales[[#This Row],[Total Amount]],0) -> 0 | V23: {=_xlfn.IFS(AND(AmazonSales[[#This Row],[Delivery Time]]=""),"",AND(AmazonSales[[#This Row],[Delivery Time]]<=2),"Fast",AND(AmazonSales[[#This Row],[Delivery Time]]>2),"Slow")} | W23: =IF(AmazonSales[[#This Row],[Delivery performance]]="Fast",1,0) -> 0
A24: 1 | B24: ORD0023 | C24: 44970 | E24: 44971 | F24: CUST016 | G24: PROD010 | H24: =_xlfn.XLOOKUP(AmazonSales[[#This Row],[Product ID]],Product_table[Product ID],Product_table[Category]) -> Fashion | I24: =_xlfn.XLOOKUP(AmazonSales[[#This Row],[Product ID]],Product_table[Product ID],Product_table[Product Name]) -> Jeans | J24: West | K24: 58 | L24: 3 | M24: 174 | N24: Amazon Pay | O24: Cancelled | P24: Amazon Logistics | Q24: =IF(AND(E24<>"", O24="Cancelled"), "Cancelled", "Active") -> Cancelled | S24: =IF(AmazonSales[[#This Row],[Order Status]]="Cancelled",1,0) -> 1 | T24: =IF(AmazonSales[[#This Row],[Delivery Status]]="Delivered",1,0) -> 0 | U24: =IF(AmazonSales[[#This Row],[Delivery Status]]="Delivered",AmazonSales[[#This Row],[Total Amount]],0) -> 0 | V24: {=_xlfn.IFS(AND(AmazonSales[[#This Row],[Delivery Time]]=""),"",AND(AmazonSales[[#This Row],[Delivery Time]]<=2),"Fast",AND(AmazonSales[[#This Row],[Delivery Time]]>2),"Slow")} | W24: =IF(AmazonSales[[#This Row],[Delivery performance]]="Fast",1,0) -> 0
A25: 1 | B25: ORD0024 | C25: 45232 | D25: 45235 | F25: CUST028 | G25: PROD006 | H25: =_xlfn.XLOOKUP(AmazonSales[[#This Row],[Product ID]],Product_table[Product ID],Product_table[Category]) -> Fashion | I25: =_xlfn.XLOOKUP(AmazonSales[[#This Row],[Product ID]],Product_table[Product ID],Product_table[Product Name]) -> Shoes | J25: West | K25: 96 | L25: 5 | M25: 480 | N25: Amazon Pay | O25: Delivered | P25: Amazon Logistics | Q25: =IF(AND(E25<>"", O25="Cancelled"), "Cancelled", "Active") -> Active | R25: =DATEDIF(AmazonSales[[#This Row],[Order Date]],AmazonSales[[#This Row],[Delivery Date]],"d") -> 3 | S25: =IF(AmazonSales[[#This Row],[Order Status]]="Cancelled",1,0) -> 0 | T25: =IF(AmazonSales[[#This Row],[Delivery Status]]="Delivered",1,0) -> 1 | U25: =IF(AmazonSales[[#This Row],[Delivery Status]]="Delivered",AmazonSales[[#This Row],[Total Amount]],0) -> 480 | V25: {=_xlfn.IFS(AND(AmazonSales[[#This Row],[Delivery Time]]=""),"",AND(AmazonSales[[#This Row],[Delivery Time]]<=2),"Fast",AND(AmazonSales[[#This Row],[Delivery Time]]>2),"Slow")} -> Slow | W25: =IF(AmazonSales[[#This Row],[Delivery performance]]="Fast",1,0) -> 0
A26: 1 | B26: ORD0025 | C26: 45074 | D26: 45076 | F26: CUST040 | G26: PROD002 | H26: =_xlfn.XLOOKUP(AmazonSales[[#This Row],[Product ID]],Product_table[Product ID],Product_table[Category]) -> Toys | I26: =_xlfn.XLOOKUP(AmazonSales[[#This Row],[Product ID]],Product_table[Product ID],Product_table[Product Name]) -> Action Figure | J26: South | K26: 43 | L26: 1 | M26: 43 | N26: Debit Card | O26: Delivered | P26: Amazon Logistics | Q26: =IF(AND(E26<>"", O26="Cancelled"), "Cancelled", "Active") -> Active | R26: =DATEDIF(AmazonSales[[#This Row],[Order Date]],AmazonSales[[#This Row],[Delivery Date]],"d") -> 2 | S26: =IF(AmazonSales[[#This Row],[Order Status]]="Cancelled",1,0) -> 0 | T26: =IF(AmazonSales[[#This Row],[Delivery Status]]="Delivered",1,0) -> 1 | U26: =IF(AmazonSales[[#This Row],[Delivery Status]]="Delivered",AmazonSales[[#This Row],[Total Amount]],0) -> 43 | V26: {=_xlfn.IFS(AND(AmazonSales[[#This Row],[Delivery Time]]=""),"",AND(AmazonSales[[#This Row],[Delivery Time]]<=2),"Fast",AND(AmazonSales[[#This Row],[Delivery Time]]>2),"Slow")} -> Fast | W26: =IF(AmazonSales[[#This Row],[Delivery performance]]="Fast",1,0) -> 1
A27: 1 | B27: ORD0026 | C27: 45214 | D27: 45220 | F27: CUST027 | G27: PROD022 | H27: =_xlfn.XLOOKUP(AmazonSales[[#This Row],[Product ID]],Product_table[Product ID],Product_table[Category]) -> Fashion | I27: =_xlfn.XLOOKUP(AmazonSales[[#This Row],[Product ID]],Product_table[Product ID],Product_table[Product Name]) -> Backpack | J27: South | K27: 64 | L27: 4 | M27: 256 | N27: Debit Card | O27: Delivered | P27: USPS | Q27: =IF(AND(E27<>"", O27="Cancelled"), "Cancelled", "Active") -> Active | R27: =DATEDIF(AmazonSales[[#This Row],[Order Date]],AmazonSales[[#This Row],[Delivery Date]],"d") -> 6 | S27: =IF(AmazonSales[[#This Row],[Order Status]]="Cancelled",1,0) -> 0 | T27: =IF(AmazonSales[[#This Row],[Delivery Status]]="Delivered",1,0) -> 1 | U27: =IF(AmazonSales[[#This Row],[Delivery Status]]="Delivered",AmazonSales[[#This Row],[Total Amount]],0) -> 256 | V27: {=_xlfn.IFS(AND(AmazonSales[[#This Row],[Delivery Time]]=""),"",AND(AmazonSales[[#This Row],[Delivery Time]]<=2),"Fast",AND(AmazonSales[[#This Row],[Delivery Time]]>2),"Slow")} -> Slow | W27: =IF(AmazonSales[[#This Row],[Delivery performance]]="Fast",1,0) -> 0
A28: 1 | B28: ORD0027 | C28: 44942 | F28: CUST018 | G28: PROD008 | H28: =_xlfn.XLOOKUP(AmazonSales[[#This Row],[Product ID]],Product_table[Product ID],Product_table[Category]) -> Books | I28: =_xlfn.XLOOKUP(AmazonSales[[#This Row],[Product ID]],Product_table[Product ID],Product_table[Product Name]) -> Textbook | J28: South | K28: 70 | L28: 2 | M28: 140 | N28: Amazon Pay | O28: In Transit | P28: Amazon Logistics | Q28: =IF(AND(E28<>"", O28="Cancelled"), "Cancelled", "Active") -> Active | S28: =IF(AmazonSales[[#This Row],[Order Status]]="Cancelled",1,0) -> 0 | T28: =IF(AmazonSales[[#This Row],[Delivery Status]]="Delivered",1,0) -> 0 | U28: =IF(AmazonSales[[#This Row],[Delivery Status]]="Delivered",AmazonSales[[#This Row],[Total Amount]],0) -> 0 | V28: {=_xlfn.IFS(AND(AmazonSales[[#This Row],[Delivery Time]]=""),"",AND(AmazonSales[[#This Row],[Delivery Time]]<=2),"Fast",AND(AmazonSales[[#This Row],[Delivery Time]]>2),"Slow")} | W28: =IF(AmazonSales[[#This Row],[Delivery performance]]="Fast",1,0) -> 0
A29: 1 | B29: ORD0028 | C29: 45179 | F29: CUST018 | G29: PROD018 | H29: =_xlfn.XLOOKUP(AmazonSales[[#This Row],[Product ID]],Product_table[Product ID],Product_table[Category]) -> Toys | I29: =_xlfn.XLOOKUP(AmazonSales[[#This Row],[Product ID]],Product_table[Product ID],Product_table[Product Name]) -> Doll House | J29: Central | K29: 97 | L29: 3 | M29: 291 | N29: Credit Card | O29: In Transit | P29: Amazon Logistics | Q29: =IF(AND(E29<>"", O29="Cancelled"), "Cancelled", "Active") -> Active | S29: =IF(AmazonSales[[#This Row],[Order Status]]="Cancelled",1,0) -> 0 | T29: =IF(AmazonSales[[#This Row],[Delivery Status]]="Delivered",1,0) -> 0 | U29: =IF(AmazonSales[[#This Row],[Delivery Status]]="Delivered",AmazonSales[[#This Row],[Total Amount]],0) -> 0 | V29: {=_xlfn.IFS(AND(AmazonSales[[#This Row],[Delivery Time]]=""),"",AND(AmazonSales[[#This Row],[Delivery Time]]<=2),"Fast",AND(AmazonSales[[#This Row],[Delivery Time]]>2),"Slow")} | W29: =IF(AmazonSales[[#This Row],[Delivery performance]]="Fast",1,0) -> 0
A30: 1 | B30: ORD0029 | C30: 45117 | E30: 45209 | F30: CUST007 | G30: PROD021 | H30: =_xlfn.XLOOKUP(AmazonSales[[#This Row],[Product ID]],Product_table[Product ID],Product_table[Category]) -> Home | I30: =_xlfn.XLOOKUP(AmazonSales[[#This Row],[Product ID]],Product_table[Product ID],Product_table[Product Name]) -> Wall Clock | J30: East | K30: 37 | L30: 3 | M30: 111 | N30: Apple Pay | O30: Cancelled | P30: DHL | Q30: =IF(AND(E30<>"", O30="Cancelled"), "Cancelled", "Active") -> Cancelled | S30: =IF(AmazonSales[[#This Row],[Order Status]]="Cancelled",1,0) -> 1 | T30: =IF(AmazonSales[[#This Row],[Delivery Status]]="Delivered",1,0) -> 0 | U30: =IF(AmazonSales[[#This Row],[Delivery Status]]="Delivered",AmazonSales[[#This Row],[Total Amount]],0) -> 0 | V30: {=_xlfn.IFS(AND(AmazonSales[[#This Row],[Delivery Time]]=""),"",AND(AmazonSales[[#This Row],[Delivery Time]]<=2),"Fast",AND(AmazonSales[[#This Row],[Delivery Time]]>2),"Slow")} | W30: =IF(AmazonSales[[#This Row],[Delivery performance]]="Fast",1,0) -> 0
A31: 1 | B31: ORD0030 | C31: 44971 | F31: CUST008 | G31: PROD008 | H31: =_xlfn.XLOOKUP(AmazonSales[[#This Row],[Product ID]],Product_table[Product ID],Product_table[Category]) -> Books | I31: =_xlfn.XLOOKUP(AmazonSales[[#This Row],[Product ID]],Product_table[Product ID],Product_table[Product Name]) -> Textbook | J31: North | K31: 69 | L31: 5 | M31: 345 | N31: Amazon Pay | O31: In Transit | P31: Amazon Logistics | Q31: =IF(AND(E31<>"", O31="Cancelled"), "Cancelled", "Active") -> Active | S31: =IF(AmazonSales[[#This Row],[Order Status]]="Cancelled",1,0) -> 0 | T31: =IF(AmazonSales[[#This Row],[Delivery Status]]="Delivered",1,0) -> 0 | U31: =IF(AmazonSales[[#This Row],[Delivery Status]]="Delivered",AmazonSales[[#This Row],[Total Amount]],0) -> 0 | V31: {=_xlfn.IFS(AND(AmazonSales[[#This Row],[Delivery Time]]=""),"",AND(AmazonSales[[#This Row],[Delivery Time]]<=2),"Fast",AND(AmazonSales[[#This Row],[Delivery Time]]>2),"Slow")} | W31: =IF(AmazonSales[[#This Row],[Delivery performance]]="Fast",1,0) -> 0
A32: 1 | B32: ORD0031 | C32: 45011 | F32: CUST014 | G32: PROD002 | H32: =_xlfn.XLOOKUP(AmazonSales[[#This Row],[Product ID]],Product_table[Product ID],Product_table[Category]) -> Toys | I32: =_xlfn.XLOOKUP(AmazonSales[[#This Row],[Product ID]],Product_table[Product ID],Product_table[Product Name]) -> Action Figure | J32: North | K32: 42 | L32: 5 | M32: 210 | N32: Amazon Pay | O32: In Transit | P32: UPS | Q32: =IF(AND(E32<>"", O32="Cancelled"), "Cancelled", "Active") -> Active | S32: =IF(AmazonSales[[#This Row],[Order Status]]="Cancelled",1,0) -> 0 | T32: =IF(AmazonSales[[#This Row],[Delivery Status]]="Delivered",1,0) -> 0 | U32: =IF(AmazonSales[[#This Row],[Delivery Status]]="Delivered",AmazonSales[[#This Row],[Total Amount]],0) -> 0 | V32: {=_xlfn.IFS(AND(AmazonSales[[#This Row],[Delivery Time]]=""),"",AND(AmazonSales[[#This Row],[Delivery Time]]<=2),"Fast",AND(AmazonSales[[#This Row],[Delivery Time]]>2),"Slow")} | W32: =IF(AmazonSales[[#This Row],[Delivery performance]]="Fast",1,0) -> 0
A33: 1 | B33: ORD0032 | C33: 45092 | E33: 45099 | F33: CUST037 | G33: PROD009 | H33: =_xlfn.XLOOKUP(AmazonSales[[#This Row],[Product ID]],Product_table[Product ID],Product_table[Category]) -> Books | I33: =_xlfn.XLOOKUP(AmazonSales[[#This Row],[Product ID]],Product_table[Product ID],Product_table[Product Name]) -> Magazine | J33: East | K33: 11 | L33: 5 | M33: 55 | N33: Debit Card | O33: Cancelled | P33: FedEx | Q33: =IF(AND(E33<>"", O33="Cancelled"), "Cancelled", "Active") -> Cancelled | S33: =IF(AmazonSales[[#This Row],[Order Status]]="Cancelled",1,0) -> 1 | T33: =IF(AmazonSales[[#This Row],[Delivery Status]]="Delivered",1,0) -> 0 | U33: =IF(AmazonSales[[#This Row],[Delivery Status]]="Delivered",AmazonSales[[#This Row],[Total Amount]],0) -> 0 | V33: {=_xlfn.IFS(AND(AmazonSales[[#This Row],[Delivery Time]]=""),"",AND(AmazonSales[[#This Row],[Delivery Time]]<=2),"Fast",AND(AmazonSales[[#This Row],[Delivery Time]]>2),"Slow")} | W33: =IF(AmazonSales[[#This Row],[Delivery performance]]="Fast",1,0) -> 0
A34: 1 | B34: ORD0033 | C34: 45068 | D34: 45069 | F34: CUST016 | G34: PROD005 | H34: =_xlfn.XLOOKUP(AmazonSales[[#This Row],[Product ID]],Product_table[Product ID],Product_table[Category]) -> Fashion | I34: =_xlfn.XLOOKUP(AmazonSales[[#This Row],[Product ID]],Product_table[Product ID],Product_table[Product Name]) -> T-Shirt | J34: South | K34: 27 | L34: 2 | M34: 54 | N34: Apple Pay | O34: Delivered | P34: USPS | Q34: =IF(AND(E34<>"", O34="Cancelled"), "Cancelled", "Active") -> Active | R34: =DATEDIF(AmazonSales[[#This Row],[Order Date]],AmazonSales[[#This Row],[Delivery Date]],"d") -> 1 | S34: =IF(AmazonSales[[#This Row],[Order Status]]="Cancelled",1,0) -> 0 | T34: =IF(AmazonSales[[#This Row],[Delivery Status]]="Delivered",1,0) -> 1 | U34: =IF(AmazonSales[[#This Row],[Delivery Status]]="Delivered",AmazonSales[[#This Row],[Total Amount]],0) -> 54 | V34: {=_xlfn.IFS(AND(AmazonSales[[#This Row],[Delivery Time]]=""),"",AND(AmazonSales[[#This Row],[Delivery Time]]<=2),"Fast",AND(AmazonSales[[#This Row],[Delivery Time]]>2),"Slow")} -> Fast | W34: =IF(AmazonSales[[#This Row],[Delivery performance]]="Fast",1,0) -> 1
A35: 1 | B35: ORD0034 | C35: 45250 | F35: CUST025 | G35: PROD015 | H35: =_xlfn.XLOOKUP(AmazonSales[[#This Row],[Product ID]],Product_table[Product ID],Product_table[Category]) -> Books | I35: =_xlfn.XLOOKUP(AmazonSales[[#This Row],[Product ID]],Product_table[Product ID],Product_table[Product Name]) -> Novel | J35: South | K35: 21 | L35: 1 | M35: 21 | N35: Amazon Pay | O35: In Transit | P35: DHL | Q35: =IF(AND(E35<>"", O35="Cancelled"), "Cancelled", "Active") -> Active | S35: =IF(AmazonSales[[#This Row],[Order Status]]="Cancelled",1,0) -> 0 | T35: =IF(AmazonSales[[#This Row],[Delivery Status]]="Delivered",1,0) -> 0 | U35: =IF(AmazonSales[[#This Row],[Delivery Status]]="Delivered",AmazonSales[[#This Row],[Total Amount]],0) -> 0 | V35: {=_xlfn.IFS(AND(AmazonSales[[#This Row],[Delivery Time]]=""),"",AND(AmazonSales[[#This Row],[Delivery Time]]<=2),"Fast",AND(AmazonSales[[#This Row],[Delivery Time]]>2),"Slow")} | W35: =IF(AmazonSales[[#This Row],[Delivery performance]]="Fast",1,0) -> 0
A36: 1 | B36: ORD0035 | C36: 45261 | D36: 45286 | F36: CUST032 | G36: PROD011 | H36: =_xlfn.XLOOKUP(AmazonSales[[#This Row],[Product ID]],Product_table[Product ID],Product_table[Category]) -> Electronics | I36: =_xlfn.XLOOKUP(AmazonSales[[#This Row],[Product ID]],Product_table[Product ID],Product_table[Product Name]) -> Headphones | J36: South | K36: 172 | L36: 1 | M36: 172 | N36: PayPal | O36: Delivered | P36: USPS | Q36: =IF(AND(E36<>"", O36="Cancelled"), "Cancelled", "Active") -> Active | R36: =DATEDIF(AmazonSales[[#This Row],[Order Date]],AmazonSales[[#This Row],[Delivery Date]],"d") -> 25 | S36: =IF(AmazonSales[[#This Row],[Order Status]]="Cancelled",1,0) -> 0 | T36: =IF(AmazonSales[[#This Row],[Delivery Status]]="Delivered",1,0) -> 1 | U36: =IF(AmazonSales[[#This Row],[Delivery Status]]="Delivered",AmazonSales[[#This Row],[Total Amount]],0) -> 172 | V36: {=_xlfn.IFS(AND(AmazonSales[[#This Row],[Delivery Time]]=""),"",AND(AmazonSales[[#This Row],[Delivery Time]]<=2),"Fast",AND(AmazonSales[[#This Row],[Delivery Time]]>2),"Slow")} -> Slow | W36: =IF(AmazonSales[[#This Row],[Delivery performance]]="Fast",1,0) -> 0
A37: 1 | B37: ORD0036 | C37: 45130 | F37: CUST014 | G37: PROD016 | H37: =_xlfn.XLOOKUP(AmazonSales[[#This Row],[Product ID]],Product_table[Product ID],Product_table[Category]) -> Home | I37: =_xlfn.XLOOKUP(AmazonSales[[#This Row],[Product ID]],Product_table[Product ID],Product_table[Product Name]) -> Cookware Set Pro | J37: North | K37: 212 | L37: 3 | M37: 636 | N37: Amazon Pay | O37: In Transit | P37: UPS | Q37: =IF(AND(E37<>"", O37="Cancelled"), "Cancelled", "Active") -> Active | S37: =IF(AmazonSales[[#This Row],[Order Status]]="Cancelled",1,0) -> 0 | T37: =IF(AmazonSales[[#This Row],[Delivery Status]]="Delivered",1,0) -> 0 | U37: =IF(AmazonSales[[#This Row],[Delivery Status]]="Delivered",AmazonSales[[#This Row],[Total Amount]],0) -> 0 | V37: {=_xlfn.IFS(AND(AmazonSales[[#This Row],[Delivery Time]]=""),"",AND(AmazonSales[[#This Row],[Delivery Time]]<=2),"Fast",AND(AmazonSales[[#This Row],[Delivery Time]]>2),"Slow")} | W37: =IF(AmazonSales[[#This Row],[Delivery performance]]="Fast",1,0) -> 0
A38: 1 | B38: ORD0037 | C38: 45216 | D38: 45221 | F38: CUST044 | G38: PROD002 | H38: =_xlfn.XLOOKUP(AmazonSales[[#This Row],[Product ID]],Product_table[Product ID],Product_table[Category]) -> Toys | I38: =_xlfn.XLOOKUP(AmazonSales[[#This Row],[Product ID]],Product_table[Product ID],Product_table[Product Name]) -> Action Figure | J38: East | K38: 41 | L38: 4 | M38: 164 | N38: Credit Card | O38: Delivered | P38: Amazon Logistics | Q38: =IF(AND(E38<>"", O38="Cancelled"), "Cancelled", "Active") -> Active | R38: =DATEDIF(AmazonSales[[#This Row],[Order Date]],AmazonSales[[#This Row],[Delivery Date]],"d") -> 5 | S38: =IF(AmazonSales[[#This Row],[Order Status]]="Cancelled",1,0) -> 0 | T38: =IF(AmazonSales[[#This Row],[Delivery Status]]="Delivered",1,0) -> 1 | U38: =IF(AmazonSales[[#This Row],[Delivery Status]]="Delivered",AmazonSales[[#This Row],[Total Amount]],0) -> 164 | V38: {=_xlfn.IFS(AND(AmazonSales[[#This Row],[Delivery Time]]=""),"",AND(AmazonSales[[#This Row],[Delivery Time]]<=2),"Fast",AND(AmazonSales[[#This Row],[Delivery Time]]>2),"Slow")} -> Slow | W38: =IF(AmazonSales[[#This Row],[Delivery performance]]="Fast",1,0) -> 0
A39: 1 | B39: ORD0038 | C39: 45160 | E39: 45162 | F39: CUST028 | G39: PROD007 | H39: =_xlfn.XLOOKUP(AmazonSales[[#This Row],[Product ID]],Product_table[Product ID],Product_table[Category]) -> Toys | I39: =_xlfn.XLOOKUP(AmazonSales[[#This Row],[Product ID]],Product_table[Product ID],Product_table[Product Name]) -> Puzzle | J39: North | K39: 32 | L39: 2 | M39: 64 | N39: Debit Card | O39: Cancelled | P39: FedEx | Q39: =IF(AND(E39<>"", O39="Cancelled"), "Cancelled", "Active") -> Cancelled | S39: =IF(AmazonSales[[#This Row],[Order Status]]="Cancelled",1,0) -> 1 | T39: =IF(AmazonSales[[#This Row],[Delivery Status]]="Delivered",1,0) -> 0 | U39: =IF(AmazonSales[[#This Row],[Delivery Status]]="Delivered",AmazonSales[[#This Row],[Total Amount]],0) -> 0 | V39: {=_xlfn.IFS(AND(AmazonSales[[#This Row],[Delivery Time]]=""),"",AND(AmazonSales[[#This Row],[Delivery Time]]<=2),"Fast",AND(AmazonSales[[#This Row],[Delivery Time]]>2),"Slow")} | W39: =IF(AmazonSales[[#This Row],[Delivery performance]]="Fast",1,0) -> 0
A40: 1 | B40: ORD0039 | C40: 44938 | F40: CUST024 | G40: PROD022 | H40: =_xlfn.XLOOKUP(AmazonSales[[#This Row],[Product ID]],Product_table[Product ID],Product_table[Category]) -> Fashion | I40: =_xlfn.XLOOKUP(AmazonSales[[#This Row],[Product ID]],Product_table[Product ID],Product_table[Product Name]) -> Backpack | J40: East | K40: 66 | L40: 2 | M40: 132 | N40: Apple Pay | O40: In Transit | P40: DHL | Q40: =IF(AND(E40<>"", O40="Cancelled"), "Cancelled", "Active") -> Active | S40: =IF(AmazonSales[[#This Row],[Order Status]]="Cancelled",1,0) -> 0 | T40: =IF(AmazonSales[[#This Row],[Delivery Status]]="Delivered",1,0) -> 0 | U40: =IF(AmazonSales[[#This Row],[Delivery Status]]="Delivered",AmazonSales[[#This Row],[Total Amount]],0) -> 0 | V40: {=_xlfn.IFS(AND(AmazonSales[[#This Row],[Delivery Time]]=""),"",AND(AmazonSales[[#This Row],[Delivery Time]]<=2),"Fast",AND(AmazonSales[[#This Row],[Delivery Time]]>2),"Slow")} | W40: =IF(AmazonSales[[#This Row],[Delivery performance]]="Fast",1,0) -> 0
...

Sheet Task2
A1: Creating Pivot Tables
A2: ● Show Total Sales Amount by Region and Product Category
A3: ● Count of Orders by Delivery Status
A4: ● Average Delivery Time = Delivery Date – Order Date
A5: ● Add filter for Payment Method and Product Category
B7: Payment Method | C7: (All)
B8: Delivery Status | C8: (All)
B9: Product Category | C9: (All)
C11: Total sales amount | D11: Count of Orders | E11: Average of Delivery Time
B12: Central | C12: 5456 | D12: 14 | E12: 4.2
B13: East | C13: 3635 | D13: 18 | E13: 8.125
B14: North | C14: 10491 | D14: 25 | E14: 3.625
B15: South | C15: 7317 | D15: 20 | E15: 6.8333333
B16: West | C16: 8359 | D16: 23 | E16: 6.8571429
B17: Grand Total | C17: 35258 | D17: 100 | E17: 6

Sheet Task3
A1: Order ID | B1: Order Date | C1: Delivery Date | D1: Cancel Date | E1: Customer ID | F1: Customer Name | G1: Product ID | H1: Region | I1: Sale Price/Unit | J1: Quantity | K1: Total Amount | L1: Payment Method | M1: Delivery Status | N1: Fulfillment Partner | O1: Delivery Performance
A2: ORD0001 | B2: 45291 | D2: 45323 | E2: CUST021 | F2: =_xlfn.XLOOKUP(AmazonSales5[[#This Row],[Customer ID]],customerdata[Customer ID],customerdata[Customer Name],"Not Found") -> Zoe Mitchell | G2: PROD012 | H2: North | I2: 44 | J2: 1 | K2: 44 | L2: Apple Pay | M2: Cancelled | N2: DHL | O2: =IFERROR(IF(AmazonSales5[[#This Row],[Delivery Date]]="", "", IF(AmazonSales5[[#This Row],[Delivery Date]]-AmazonSales5[[#This Row],[Order Date]]<=2,"Fast","Slow")),"")
A3: ORD0002 | B3: 44979 | C3: 44981 | E3: CUST029 | F3: =_xlfn.XLOOKUP(AmazonSales5[[#This Row],[Customer ID]],customerdata[Customer ID],customerdata[Customer Name],"Not Found") -> Ava White | G3: PROD018 | H3: East | I3: 96 | J3: 4 | K3: 384 | L3: Credit Card | M3: Delivered | N3: DHL | O3: =IFERROR(IF(AmazonSales5[[#This Row],[Delivery Date]]="", "", IF(AmazonSales5[[#This Row],[Delivery Date]]-AmazonSales5[[#This Row],[Order Date]]<=2,"Fast","Slow")),"") -> Fast
A4: ORD0003 | B4: 45240 | E4: CUST021 | F4: =_xlfn.XLOOKUP(AmazonSales5[[#This Row],[Customer ID]],customerdata[Customer ID],customerdata[Customer Name],"Not Found") -> Zoe Mitchell | G4: PROD013 | H4: South | I4: 194 | J4: 4 | K4: 776 | L4: Credit Card | M4: In Transit | N4: USPS | O4: =IFERROR(IF(AmazonSales5[[#This Row],[Delivery Date]]="", "", IF(AmazonSales5[[#This Row],[Delivery Date]]-AmazonSales5[[#This Row],[Order Date]]<=2,"Fast","Slow")),"")
A5: ORD0004 | B5: 45051 | D5: 45235 | E5: CUST044 | F5: =_xlfn.XLOOKUP(AmazonSales5[[#This Row],[Customer ID]],customerdata[Customer ID],customerdata[Customer Name],"Not Found") -> Grace Ward | G5: PROD013 | H5: North | I5: 196 | J5: 3 | K5: 588 | L5: PayPal | M5: Cancelled | N5: UPS | O5: =IFERROR(IF(AmazonSales5[[#This Row],[Delivery Date]]="", "", IF(AmazonSales5[[#This Row],[Delivery Date]]-AmazonSales5[[#This Row],[Order Date]]<=2,"Fast","Slow")),"")
A6: ORD0005 | B6: 44959 | C6: 45048 | E6: CUST027 | F6: =_xlfn.XLOOKUP(AmazonSales5[[#This Row],[Customer ID]],customerdata[Customer ID],customerdata[Customer Name],"Not Found") -> Hazel Brooks | G6: PROD010 | H6: North | I6: 59 | J6: 1 | K6: 59 | L6: PayPal | M6: Delivered | N6: Amazon Logistics | O6: =IFERROR(IF(AmazonSales5[[#This Row],[Delivery Date]]="", "", IF(AmazonSales5[[#This Row],[Delivery Date]]-AmazonSales5[[#This Row],[Order Date]]<=2,"Fast","Slow")),"") -> Slow
A7: ORD0006 | B7: 44937 | D7: 44968 | E7: CUST009 | F7: =_xlfn.XLOOKUP(AmazonSales5[[#This Row],[Customer ID]],customerdata[Customer ID],customerdata[Customer Name],"Not Found") -> Jackson Allen | G7: PROD010 | H7: North | I7: 58 | J7: 4 | K7: 232 | L7: Amazon Pay | M7: Cancelled | N7: DHL | O7: =IFERROR(IF(AmazonSales5[[#This Row],[Delivery Date]]="", "", IF(AmazonSales5[[#This Row],[Delivery Date]]-AmazonSales5[[#This Row],[Order Date]]<=2,"Fast","Slow")),"")
A8: ORD0007 | B8: 45152 | D8: 45156 | E8: CUST042 | F8: =_xlfn.XLOOKUP(AmazonSales5[[#This Row],[Customer ID]],customerdata[Customer ID],customerdata[Customer Name],"Not Found") -> Noah Wilson | G8: PROD020 | H8: Central | I8: 105 | J8: 3 | K8: 315 | L8: Debit Card | M8: Cancelled | N8: DHL | O8: =IFERROR(IF(AmazonSales5[[#This Row],[Delivery Date]]="", "", IF(AmazonSales5[[#This Row],[Delivery Date]]-AmazonSales5[[#This Row],[Order Date]]<=2,"Fast","Slow")),"")
A9: ORD0008 | B9: 44930 | D9: 45081 | E9: CUST019 | F9: =_xlfn.XLOOKUP(AmazonSales5[[#This Row],[Customer ID]],customerdata[Customer ID],customerdata[Customer Name],"Not Found") -> Ava Robinson | G9: PROD021 | H9: West | I9: 37 | J9: 5 | K9: 185 | L9: PayPal | M9: Cancelled | N9: DHL | O9: =IFERROR(IF(AmazonSales5[[#This Row],[Delivery Date]]="", "", IF(AmazonSales5[[#This Row],[Delivery Date]]-AmazonSales5[[#This Row],[Order Date]]<=2,"Fast","Slow")),"")
A10: ORD0009 | B10: 45128 | E10: CUST013 | F10: =_xlfn.XLOOKUP(AmazonSales5[[#This Row],[Customer ID]],customerdata[Customer ID],customerdata[Customer Name],"Not Found") -> Olivia Martinez | G10: PROD019 | H10: Central | I10: 44 | J10: 2 | K10: 88 | L10: Credit Card | M10: In Transit | N10: Amazon Logistics | O10: =IFERROR(IF(AmazonSales5[[#This Row],[Delivery Date]]="", "", IF(AmazonSales5[[#This Row],[Delivery Date]]-AmazonSales5[[#This Row],[Order Date]]<=2,"Fast","Slow")),"")
A11: ORD0010 | B11: 45289 | E11: CUST019 | F11: =_xlfn.XLOOKUP(AmazonSales5[[#This Row],[Customer ID]],customerdata[Customer ID],customerdata[Customer Name],"Not Found") -> Ava Robinson | G11: PROD003 | H11: South | I11: 141 | J11: 4 | K11: 564 | L11: Debit Card | M11: In Transit | N11: DHL | O11: =IFERROR(IF(AmazonSales5[[#This Row],[Delivery Date]]="", "", IF(AmazonSales5[[#This Row],[Delivery Date]]-AmazonSales5[[#This Row],[Order Date]]<=2,"Fast","Slow")),"")
A12: ORD0011 | B12: 45021 | D12: 45143 | E12: CUST046 | F12: =_xlfn.XLOOKUP(AmazonSales5[[#This Row],[Customer ID]],customerdata[Customer ID],customerdata[Customer Name],"Not Found") -> Emily Johnson | G12: PROD014 | H12: South | I12: 249 | J12: 1 | K12: 249 | L12: Amazon Pay | M12: Cancelled | N12: USPS | O12: =IFERROR(IF(AmazonSales5[[#This Row],[Delivery Date]]="", "", IF(AmazonSales5[[#This Row],[Delivery Date]]-AmazonSales5[[#This Row],[Order Date]]<=2,"Fast","Slow")),"")
A13: ORD0012 | B13: 45132 | E13: CUST045 | F13: =_xlfn.XLOOKUP(AmazonSales5[[#This Row],[Customer ID]],customerdata[Customer ID],customerdata[Customer Name],"Not Found") -> Emily Johnson | G13: PROD014 | H13: Central | I13: 247 | J13: 3 | K13: 741 | L13: Amazon Pay | M13: In Transit | N13: FedEx | O13: =IFERROR(IF(AmazonSales5[[#This Row],[Delivery Date]]="", "", IF(AmazonSales5[[#This Row],[Delivery Date]]-AmazonSales5[[#This Row],[Order Date]]<=2,"Fast","Slow")),"")
A14: ORD0013 | B14: 44982 | D14: 44985 | E14: CUST023 | F14: =_xlfn.XLOOKUP(AmazonSales5[[#This Row],[Customer ID]],customerdata[Customer ID],customerdata[Customer Name],"Not Found") -> Charlotte Reed | G14: PROD006 | H14: Central | I14: 96 | J14: 1 | K14: 96 | L14: Apple Pay | M14: Cancelled | N14: Amazon Logistics | O14: =IFERROR(IF(AmazonSales5[[#This Row],[Delivery Date]]="", "", IF(AmazonSales5[[#This Row],[Delivery Date]]-AmazonSales5[[#This Row],[Order Date]]<=2,"Fast","Slow")),"")
A15: ORD0014 | B15: 44981 | D15: 44982 | E15: CUST033 | F15: =_xlfn.XLOOKUP(AmazonSales5[[#This Row],[Customer ID]],customerdata[Customer ID],customerdata[Customer Name],"Not Found") -> Hazel Rivera | G15: PROD017 | H15: West | I15: 74 | J15: 5 | K15: 370 | L15: Apple Pay | M15: Cancelled | N15: Amazon Logistics | O15: =IFERROR(IF(AmazonSales5[[#This Row],[Delivery Date]]="", "", IF(AmazonSales5[[#This Row],[Delivery Date]]-AmazonSales5[[#This Row],[Order Date]]<=2,"Fast","Slow")),"")
A16: ORD0015 | B16: 45164 | D16: 45171 | E16: CUST033 | F16: =_xlfn.XLOOKUP(AmazonSales5[[#This Row],[Customer ID]],customerdata[Customer ID],customerdata[Customer Name],"Not Found") -> Hazel Rivera | G16: PROD005 | H16: South | I16: 27 | J16: 1 | K16: 27 | L16: Credit Card | M16: Cancelled | N16: Amazon Logistics | O16: =IFERROR(IF(AmazonSales5[[#This Row],[Delivery Date]]="", "", IF(AmazonSales5[[#This Row],[Delivery Date]]-AmazonSales5[[#This Row],[Order Date]]<=2,"Fast","Slow")),"")
A17: ORD0016 | B17: 44970 | E17: CUST047 | F17: =_xlfn.XLOOKUP(AmazonSales5[[#This Row],[Customer ID]],customerdata[Customer ID],customerdata[Customer Name],"Not Found") -> Scarlett Murphy | G17: PROD005 | H17: South | I17: 27 | J17: 3 | K17: 81 | L17: Debit Card | M17: In Transit | N17: Amazon Logistics | O17: =IFERROR(IF(AmazonSales5[[#This Row],[Delivery Date]]="", "", IF(AmazonSales5[[#This Row],[Delivery Date]]-AmazonSales5[[#This Row],[Order Date]]<=2,"Fast","Slow")),"")
A18: ORD0017 | B18: 45105 | C18: 44933 | E18: CUST045 | F18: =_xlfn.XLOOKUP(AmazonSales5[[#This Row],[Customer ID]],customerdata[Customer ID],customerdata[Customer Name],"Not Found") -> Emily Johnson | G18: PROD015 | H18: East | I18: 21 | J18: 3 | K18: 63 | L18: Credit Card | M18: Delivered | N18: DHL | O18: =IFERROR(IF(AmazonSales5[[#This Row],[Delivery Date]]="", "", IF(AmazonSales5[[#This Row],[Delivery Date]]-AmazonSales5[[#This Row],[Order Date]]<=2,"Fast","Slow")),"") -> Fast
